# إصلاح Flow Exception Transparency Violation

## 🚨 **المشكلة:**
```
Flow exception transparency is violated: Previous 'emit' call has thrown exception kotlinx.coroutines.flow.internal.AbortFlowException: Flow was aborted, no more elements needed, but then emission attempt of value 'com.company.npw.core.util.Resource$Error@f15a9aa' has been detected.
Emissions from 'catch' blocks are prohibited in order to avoid unspecified behaviour, 'Flow.catch' operator can be used instead.
```

## 🔍 **السبب:**
في `AuthRepositoryImpl.getCurrentUser()` كان هناك استخدام خاطئ لـ `.catch` مع `emit`:

### **الكود الخاطئ:**
```kotlin
override fun getCurrentUser(): Flow<Resource<User?>> = flow {
    try {
        // ... code
    } catch (e: Exception) {
        emit(Resource.Error<User?>(e.message ?: "Unknown error"))
    }
}.catch { e ->
    emit(Resource.Error<User?>(e.message ?: "Failed to get current user")) // ❌ خطأ!
}
```

## ✅ **الحل:**
إزالة `.catch` block واستخدام `try-catch` فقط داخل `flow`:

### **الكود الصحيح:**
```kotlin
override fun getCurrentUser(): Flow<Resource<User?>> = flow {
    try {
        emit(Resource.Loading<User?>())

        val currentUser = firebaseAuthService.currentUser
        if (currentUser != null) {
            val user = User(
                id = currentUser.uid,
                email = currentUser.email ?: "",
                name = currentUser.displayName ?: "",
                profileImageUrl = currentUser.photoUrl?.toString() ?: "",
                isEmailVerified = currentUser.isEmailVerified
            )
            emit(Resource.Success<User?>(user))
        } else {
            emit(Resource.Success<User?>(null))
        }
    } catch (e: Exception) {
        emit(Resource.Error<User?>(e.message ?: "Failed to get current user"))
    }
}
```

## 📚 **القاعدة العامة:**

### **✅ الطريقة الصحيحة:**
```kotlin
fun someFlow(): Flow<Resource<Data>> = flow {
    try {
        emit(Resource.Loading())
        // ... operations
        emit(Resource.Success(data))
    } catch (e: Exception) {
        emit(Resource.Error(e.message ?: "Error"))
    }
}
```

### **❌ الطريقة الخاطئة:**
```kotlin
fun someFlow(): Flow<Resource<Data>> = flow {
    try {
        // ... operations
        emit(Resource.Success(data))
    } catch (e: Exception) {
        emit(Resource.Error(e.message ?: "Error"))
    }
}.catch { e ->
    emit(Resource.Error(e.message ?: "Error")) // ❌ ممنوع!
}
```

## 🔧 **البدائل لـ Flow.catch:**

### **1. استخدام onCompletion:**
```kotlin
.onCompletion { cause ->
    if (cause != null) {
        // Handle completion with exception
    }
}
```

### **2. استخدام catch بدون emit:**
```kotlin
.catch { e ->
    // Log error or handle it
    // لكن لا تستخدم emit هنا
}
```

### **3. معالجة الأخطاء في المستقبل:**
```kotlin
.catch { e ->
    // Transform to another flow
    emitAll(flowOf(Resource.Error(e.message)))
}
```

## 🎯 **النتيجة:**
- ✅ تم إصلاح Flow exception transparency violation
- ✅ تحسين معالجة الأخطاء في Authentication
- ✅ منع الكراش عند تسجيل الدخول
- ✅ تحسين استقرار التطبيق

## 📝 **ملاحظات للمطورين:**
1. **لا تستخدم `emit` داخل `.catch` blocks**
2. **استخدم `try-catch` داخل `flow` builder**
3. **استخدم `emitAll` أو `flowOf` في `.catch` إذا لزم الأمر**
4. **اختبر Flow operations جيداً لتجنب هذه المشاكل**
